Workbook

Sheet Raw_Data
A1: customer_id | B1: age | C1: senior_citizen | D1: partner | E1: dependents | F1: tenure_months | G1: phone_service | H1: multiple_lines | I1: internet_service | J1: contract | K1: paperless_billing | L1: payment_method | M1: monthly_charges | N1: total_charges | O1: city | P1: churn
A2: CUST-00001 | B2: 58 | C2: No | D2: Yes | E2: Yes | F2: 36 | G2: Yes | H2: No | I2: Fiber optic | J2: One year | K2: Yes | L2: Credit card (automatic) | M2: 71.59 | N2: 2451.58 | O2: Faisalabad | P2: No
A3: CUST-00002 | B3: 19 | C3: No | D3: Yes | E3: No | F3: 29 | G3: No | H3: No phone service | I3: Fiber optic | J3: Two year | K3: Yes | L3: Bank transfer (automatic) | M3: 77.98 | N3: 2240.42 | O3: Karachi | P3: No
A4: CUST-00003 | B4: 66 | C4: Yes | D4: No | E4: Yes | F4: 12 | G4: No | H4: No phone service | I4: Fiber optic | J4: Two year | K4: No | L4: Bank transfer (automatic) | M4: 106.49 | N4: 1283.44 | O4: Rawalpindi | P4: No
A5: CUST-00004 | B5: 23 | C5: No | D5: No | E5: No | F5: 25 | G5: Yes | H5: No | I5: DSL | J5: One year | K5: Yes | L5: Mailed check | M5: 74.66 | N5: 1839.65 | O5: Peshawar | P5: No
A6: CUST-00005 | B6: 41 | C6: No | D6: Yes | E6: No | F6: 46 | G6: No | H6: No phone service | I6: Fiber optic | J6: One year | K6: Yes | L6: Bank transfer (automatic) | M6: 78.56 | N6: 3713.12 | O6: Rawalpindi | P6: Yes
A7: CUST-00006 | B7: 35 | C7: No | D7: Yes | E7: No | F7: 8 | G7: Yes | H7: No | I7: Fiber optic | J7: Month-to-month | K7: Yes | L7: Electronic check | M7: 117.15 | N7: 979.53 | O7: Multan | P7: Yes
A8: CUST-00007 | B8: 49 | C8: No | D8: No | E8: No | F8: 19 | G8: Yes | H8: No | I8: Fiber optic | J8: Month-to-month | K8: No | L8: Mailed check | M8: 89.97 | N8: 1651.85 | O8: Faisalabad | P8: No
A9: CUST-00008 | B9: 49 | C9: No | D9: Yes | E9: Yes | F9: 15 | G9: Yes | H9: No | I9: Fiber optic | J9: Month-to-month | K9: Yes | L9: Credit card (automatic) | M9: 99.79 | N9: 1491.11 | O9: Faisalabad | P9: Yes
A10: CUST-00009 | B10: 73 | C10: Yes | D10: Yes | E10: Yes | F10: 69 | G10: No | H10: No phone service | I10: DSL | J10: Month-to-month | K10: No | L10: Electronic check | M10: 40.13 | N10: 2842.77 | O10: Faisalabad | P10: No
A11: CUST-00010 | B11: 66 | C11: Yes | D11: Yes | E11: Yes | F11: 39 | G11: Yes | H11: Yes | I11: No | J11: One year | K11: Yes | L11: Credit card (automatic) | M11: 23.86 | N11: 887.2 | O11: Peshawar | P11: No
A12: CUST-00011 | B12: 69 | C12: Yes | D12: No | E12: Yes | F12: 8 | G12: Yes | H12: Yes | I12: Fiber optic | J12: Month-to-month | K12: Yes | L12: Mailed check | M12: 96.64 | N12: 738.4 | O12: Faisalabad | P12: No
A13: CUST-00012 | B13: 28 | C13: No | D13: No | E13: No | F13: 28 | G13: Yes | H13: No | I13: No | J13: Month-to-month | K13: No | L13: Credit card (automatic) | M13: 24.21 | N13: 647.05 | O13: Islamabad | P13: Yes
... A1001: CUST-01000 | B1001: 49 | C1001: No | D1001: No | E1001: No | F1001: 59 | G1001: Yes | H1001: No | I1001: DSL | J1001: Two year | K1001: Yes | L1001: Electronic check | M1001: 65.48 | N1001: 3712.35 | O1001: Islamabad | P1001: No

Sheet Cleaned_Data
A1: customer_id | B1: age | C1: senior_citizen | D1: partner | E1: dependents | F1: tenure_months | G1: phone_service | H1: multiple_lines | I1: internet_service | J1: contract | K1: paperless_billing | L1: payment_method | M1: monthly_charges | N1: total_charges | O1: city | P1: churn | Q1: Churn_Flag | R1: Tenure_Group | S1: Monthly_Charges_Group
A2: CUST-00001 | B2: 58 | C2: No | D2: Yes | E2: Yes | F2: 36 | G2: Yes | H2: No | I2: Fiber optic | J2: One year | K2: Yes | L2: Credit card | M2: 71.59 | N2: 2451.58 | O2: Faisalabad | P2: No | Q2: =IF(P2="Yes",1,0) -> 0 | R2: =IF(F2<=12,"0-12 months",IF(F2<=24,"13-24 months",IF(F2<=48,"25-48 months","49+ months"))) -> 25-48 months | S2: =IF(M2<50,"< $50",IF(M2<=75,"$50-$75",IF(M2<=100,"$76-$100","> $100"))) -> $50-$75
A3: CUST-00002 | B3: 19 | C3: No | D3: Yes | E3: No | F3: 29 | G3: No | H3: No phone service | I3: Fiber optic | J3: Two year | K3: Yes | L3: Bank Transfer | M3: 77.98 | N3: 2240.42 | O3: Karachi | P3: No | Q3: =IF(P3="Yes",1,0) -> 0 | R3: =IF(F3<=12,"0-12 months",IF(F3<=24,"13-24 months",IF(F3<=48,"25-48 months","49+ months"))) -> 25-48 months | S3: =IF(M3<50,"< $50",IF(M3<=75,"$50-$75",IF(M3<=100,"$76-$100","> $100"))) -> $76-$100
A4: CUST-00003 | B4: 66 | C4: Yes | D4: No | E4: Yes | F4: 12 | G4: No | H4: No phone service | I4: Fiber optic | J4: Two year | K4: No | L4: Bank Transfer | M4: 106.49 | N4: 1283.44 | O4: Rawalpindi | P4: No | Q4: =IF(P4="Yes",1,0) -> 0 | R4: =IF(F4<=12,"0-12 months",IF(F4<=24,"13-24 months",IF(F4<=48,"25-48 months","49+ months"))) -> 0-12 months | S4: =IF(M4<50,"< $50",IF(M4<=75,"$50-$75",IF(M4<=100,"$76-$100","> $100"))) -> > $100
A5: CUST-00004 | B5: 23 | C5: No | D5: No | E5: No | F5: 25 | G5: Yes | H5: No | I5: DSL | J5: One year | K5: Yes | L5: Mailed check | M5: 74.66 | N5: 1839.65 | O5: Peshawar | P5: No | Q5: =IF(P5="Yes",1,0) -> 0 | R5: =IF(F5<=12,"0-12 months",IF(F5<=24,"13-24 months",IF(F5<=48,"25-48 months","49+ months"))) -> 25-48 months | S5: =IF(M5<50,"< $50",IF(M5<=75,"$50-$75",IF(M5<=100,"$76-$100","> $100"))) -> $50-$75
A6: CUST-00005 | B6: 41 | C6: No | D6: Yes | E6: No | F6: 46 | G6: No | H6: No phone service | I6: Fiber optic | J6: One year | K6: Yes | L6: Bank Transfer | M6: 78.56 | N6: 3713.12 | O6: Rawalpindi | P6: Yes | Q6: =IF(P6="Yes",1,0) -> 1 | R6: =IF(F6<=12,"0-12 months",IF(F6<=24,"13-24 months",IF(F6<=48,"25-48 months","49+ months"))) -> 25-48 months | S6: =IF(M6<50,"< $50",IF(M6<=75,"$50-$75",IF(M6<=100,"$76-$100","> $100"))) -> $76-$100
A7: CUST-00006 | B7: 35 | C7: No | D7: Yes | E7: No | F7: 8 | G7: Yes | H7: No | I7: Fiber optic | J7: Month-to-month | K7: Yes | L7: Electronic check | M7: 117.15 | N7: 979.53 | O7: Multan | P7: Yes | Q7: =IF(P7="Yes",1,0) -> 1 | R7: =IF(F7<=12,"0-12 months",IF(F7<=24,"13-24 months",IF(F7<=48,"25-48 months","49+ months"))) -> 0-12 months | S7: =IF(M7<50,"< $50",IF(M7<=75,"$50-$75",IF(M7<=100,"$76-$100","> $100"))) -> > $100
A8: CUST-00007 | B8: 49 | C8: No | D8: No | E8: No | F8: 19 | G8: Yes | H8: No | I8: Fiber optic | J8: Month-to-month | K8: No | L8: Mailed check | M8: 89.97 | N8: 1651.85 | O8: Faisalabad | P8: No | Q8: =IF(P8="Yes",1,0) -> 0 | R8: =IF(F8<=12,"0-12 months",IF(F8<=24,"13-24 months",IF(F8<=48,"25-48 months","49+ months"))) -> 13-24 months | S8: =IF(M8<50,"< $50",IF(M8<=75,"$50-$75",IF(M8<=100,"$76-$100","> $100"))) -> $76-$100
A9: CUST-00008 | B9: 49 | C9: No | D9: Yes | E9: Yes | F9: 15 | G9: Yes | H9: No | I9: Fiber optic | J9: Month-to-month | K9: Yes | L9: Credit card | M9: 99.79 | N9: 1491.11 | O9: Faisalabad | P9: Yes | Q9: =IF(P9="Yes",1,0) -> 1 | R9: =IF(F9<=12,"0-12 months",IF(F9<=24,"13-24 months",IF(F9<=48,"25-48 months","49+ months"))) -> 13-24 months | S9: =IF(M9<50,"< $50",IF(M9<=75,"$50-$75",IF(M9<=100,"$76-$100","> $100"))) -> $76-$100
A10: CUST-00009 | B10: 73 | C10: Yes | D10: Yes | E10: Yes | F10: 69 | G10: No | H10: No phone service | I10: DSL | J10: Month-to-month | K10: No | L10: Electronic check | M10: 40.13 | N10: 2842.77 | O10: Faisalabad | P10: No | Q10: =IF(P10="Yes",1,0) -> 0 | R10: =IF(F10<=12,"0-12 months",IF(F10<=24,"13-24 months",IF(F10<=48,"25-48 months","49+ months"))) -> 49+ months | S10: =IF(M10<50,"< $50",IF(M10<=75,"$50-$75",IF(M10<=100,"$76-$100","> $100"))) -> < $50
A11: CUST-00010 | B11: 66 | C11: Yes | D11: Yes | E11: Yes | F11: 39 | G11: Yes | H11: Yes | I11: No internet | J11: One year | K11: Yes | L11: Credit card | M11: 23.86 | N11: 887.2 | O11: Peshawar | P11: No | Q11: =IF(P11="Yes",1,0) -> 0 | R11: =IF(F11<=12,"0-12 months",IF(F11<=24,"13-24 months",IF(F11<=48,"25-48 months","49+ months"))) -> 25-48 months | S11: =IF(M11<50,"< $50",IF(M11<=75,"$50-$75",IF(M11<=100,"$76-$100","> $100"))) -> < $50
A12: CUST-00011 | B12: 69 | C12: Yes | D12: No | E12: Yes | F12: 8 | G12: Yes | H12: Yes | I12: Fiber optic | J12: Month-to-month | K12: Yes | L12: Mailed check | M12: 96.64 | N12: 738.4 | O12: Faisalabad | P12: No | Q12: =IF(P12="Yes",1,0) -> 0 | R12: =IF(F12<=12,"0-12 months",IF(F12<=24,"13-24 months",IF(F12<=48,"25-48 months","49+ months"))) -> 0-12 months | S12: =IF(M12<50,"< $50",IF(M12<=75,"$50-$75",IF(M12<=100,"$76-$100","> $100"))) -> $76-$100
A13: CUST-00012 | B13: 28 | C13: No | D13: No | E13: No | F13: 28 | G13: Yes | H13: No | I13: No internet | J13: Month-to-month | K13: No | L13: Credit card | M13: 24.21 | N13: 647.05 | O13: Islamabad | P13: Yes | Q13: =IF(P13="Yes",1,0) -> 1 | R13: =IF(F13<=12,"0-12 months",IF(F13<=24,"13-24 months",IF(F13<=48,"25-48 months","49+ months"))) -> 25-48 months | S13: =IF(M13<50,"< $50",IF(M13<=75,"$50-$75",IF(M13<=100,"$76-$100","> $100"))) -> < $50
... A1001: CUST-01000 | B1001: 49 | C1001: No | D1001: No | E1001: No | F1001: 59 | G1001: Yes | H1001: No | I1001: DSL | J1001: Two year | K1001: Yes | L1001: Electronic check | M1001: 65.48 | N1001: 3712.35 | O1001: Islamabad | P1001: No | Q1001: =IF(P1001="Yes",1,0) -> 0 | R1001: =IF(F1001<=12,"0-12 months",IF(F1001<=24,"13-24 months",IF(F1001<=48,"25-48 months","49+ months"))) -> 49+ months | S1001: =IF(M1001<50,"< $50",IF(M1001<=75,"$50-$75",IF(M1001<=100,"$76-$100","> $100"))) -> $50-$75

Sheet EDA
A1: Customer Churn Analysis — EDA
A2: Metric | B2: Value
A3: Total Customers | B3: =COUNTA(Cleaned_Data!A2:A1001) -> 1000
A4: Churned Customers | B4: =COUNTIF(Cleaned_Data!P2:P1001,"Yes") -> 308
A5: Stayed Customers | B5: =COUNTIF(Cleaned_Data!P2:P1001,"No") -> 692
A6: Overall Churn Rate | B6: =B4/B3 -> 0.308
A8: Churn by Contract
A9: Contract | B9: Total Customers | C9: Churned | D9: Stayed | E9: Churn Rate
A10: Month-to-month | B10: =COUNTIF(Cleaned_Data!J2:J1001,"Month-to-month") -> 550 | C10: =COUNTIFS(Cleaned_Data!J2:J1001,"Month-to-month",Cleaned_Data!P2:P1001,"Yes") -> 211 | D10: =COUNTIFS(Cleaned_Data!J2:J1001,"Month-to-month",Cleaned_Data!P2:P1001,"No") -> 339 | E10: =C10/B10 -> 0.38363636
A11: One year | B11: =COUNTIF(Cleaned_Data!J2:J1001,"One year") -> 248 | C11: =COUNTIFS(Cleaned_Data!J2:J1001,"One year",Cleaned_Data!P2:P1001,"Yes") -> 56 | D11: =COUNTIFS(Cleaned_Data!J2:J1001,"One year",Cleaned_Data!P2:P1001,"No") -> 192 | E11: =C11/B11 -> 0.22580645
A12: Two year | B12: =COUNTIF(Cleaned_Data!J2:J1001,"Two year") -> 202 | C12: =COUNTIFS(Cleaned_Data!J2:J1001,"Two year",Cleaned_Data!P2:P1001,"Yes") -> 41 | D12: =COUNTIFS(Cleaned_Data!J2:J1001,"Two year",Cleaned_Data!P2:P1001,"No") -> 161 | E12: =C12/B12 -> 0.2029703
A14: Churn by Tenure Group
A15: Tenure Group | B15: Total Customers | C15: Churned | D15: Stayed | E15: Churn Rate
A16: 0–12 months | B16: =COUNTIFS(Cleaned_Data!F2:F1001,">=0",Cleaned_Data!F2:F1001,"<=12") -> 164 | C16: =COUNTIFS(Cleaned_Data!F2:F1001,">=0",Cleaned_Data!F2:F1001,"<=12",Cleaned_Data!P2:P1001,"Yes") -> 61 | D16: =COUNTIFS(Cleaned_Data!F2:F1001,">=0",Cleaned_Data!F2:F1001,"<=12",Cleaned_Data!P2:P1001,"No") -> 103 | E16: =C16/B16 -> 0.37195122
A17: 13–24 months | B17: =COUNTIFS(Cleaned_Data!F2:F1001,">=13",Cleaned_Data!F2:F1001,"<=24") -> 168 | C17: =COUNTIFS(Cleaned_Data!F2:F1001,">=13",Cleaned_Data!F2:F1001,"<=24",Cleaned_Data!P2:P1001,"Yes") -> 48 | D17: =COUNTIFS(Cleaned_Data!F2:F1001,">=13",Cleaned_Data!F2:F1001,"<=24",Cleaned_Data!P2:P1001,"No") -> 120 | E17: =C17/B17 -> 0.28571429
A18: 25–48 months | B18: =COUNTIFS(Cleaned_Data!F2:F1001,">=25",Cleaned_Data!F2:F1001,"<=48") -> 322 | C18: =COUNTIFS(Cleaned_Data!F2:F1001,">=25",Cleaned_Data!F2:F1001,"<=48",Cleaned_Data!P2:P1001,"Yes") -> 92 | D18: =COUNTIFS(Cleaned_Data!F2:F1001,">=25",Cleaned_Data!F2:F1001,"<=48",Cleaned_Data!P2:P1001,"No") -> 230 | E18: =C18/B18 -> 0.28571429
A19: 49+ months | B19: =COUNTIFS(Cleaned_Data!F2:F1001,">=49",Cleaned_Data!F2:F1001,"<=999") -> 346 | C19: =COUNTIFS(Cleaned_Data!F2:F1001,">=49",Cleaned_Data!F2:F1001,"<=999",Cleaned_Data!P2:P1001,"Yes") -> 107 | D19: =COUNTIFS(Cleaned_Data!F2:F1001,">=49",Cleaned_Data!F2:F1001,"<=999",Cleaned_Data!P2:P1001,"No") -> 239 | E19: =C19/B19 -> 0.30924855
A21: Churn by Payment Method
A22: Payment Method | B22: Total Customers | C22: Churned | D22: Stayed | E22: Churn Rate
A23: Bank transfer | B23: =COUNTIF(Cleaned_Data!L2:L1001,"Bank transfer") -> 249 | C23: =COUNTIFS(Cleaned_Data!L2:L1001,"Bank transfer",Cleaned_Data!P2:P1001,"Yes") -> 72 | D23: =COUNTIFS(Cleaned_Data!L2:L1001,"Bank transfer",Cleaned_Data!P2:P1001,"No") -> 177 | E23: =C23/B23 -> 0.28915663
A24: Credit card | B24: =COUNTIF(Cleaned_Data!L2:L1001,"Credit card") -> 248 | C24: =COUNTIFS(Cleaned_Data!L2:L1001,"Credit card",Cleaned_Data!P2:P1001,"Yes") -> 71 | D24: =COUNTIFS(Cleaned_Data!L2:L1001,"Credit card",Cleaned_Data!P2:P1001,"No") -> 177 | E24: =C24/B24 -> 0.28629032
A25: Mailed check | B25: =COUNTIF(Cleaned_Data!L2:L1001,"Mailed check") -> 153 | C25: =COUNTIFS(Cleaned_Data!L2:L1001,"Mailed check",Cleaned_Data!P2:P1001,"Yes") -> 39 | D25: =COUNTIFS(Cleaned_Data!L2:L1001,"Mailed check",Cleaned_Data!P2:P1001,"No") -> 114 | E25: =C25/B25 -> 0.25490196
A26: Electronic check | B26: =COUNTIF(Cleaned_Data!L2:L1001,"Electronic check") -> 350 | C26: =COUNTIFS(Cleaned_Data!L2:L1001,"Electronic check",Cleaned_Data!P2:P1001,"Yes") -> 126 | D26: =COUNTIFS(Cleaned_Data!L2:L1001,"Electronic check",Cleaned_Data!P2:P1001,"No") -> 224 | E26: =C26/B26 -> 0.36
A28: Churn by Internet Service
A29: Internet Service | B29: Total Customers | C29: Churned | D29: Stayed | E29: Churn Rate
A30: DSL | B30: =COUNTIF(Cleaned_Data!I2:I1001,"DSL") -> 360 | C30: =COUNTIFS(Cleaned_Data!I2:I1001,"DSL",Cleaned_Data!P2:P1001,"Yes") -> 92 | D30: =COUNTIFS(Cleaned_Data!I2:I1001,"DSL",Cleaned_Data!P2:P1001,"No") -> 268 | E30: =C30/B30 -> 0.25555556
A31: Fiber optic | B31: =COUNTIF(Cleaned_Data!I2:I1001,"Fiber optic") -> 430 | C31: =COUNTIFS(Cleaned_Data!I2:I1001,"Fiber optic",Cleaned_Data!P2:P1001,"Yes") -> 155 | D31: =COUNTIFS(Cleaned_Data!I2:I1001,"Fiber optic",Cleaned_Data!P2:P1001,"No") -> 275 | E31: =C31/B31 -> 0.36046512
A32: No internet | B32: =COUNTIF(Cleaned_Data!I2:I1001,"No internet") -> 210 | C32: =COUNTIFS(Cleaned_Data!I2:I1001,"No internet",Cleaned_Data!P2:P1001,"Yes") -> 61 | D32: =COUNTIFS(Cleaned_Data!I2:I1001,"No internet",Cleaned_Data!P2:P1001,"No") -> 149 | E32: =C32/B32 -> 0.29047619
A34: Churn by Monthly Charges
A35: Charge Group | B35: Total Customers | C35: Churned | D35: Stayed | E35: Churn Rate
A36: < $50 | B36: =COUNTIFS(Cleaned_Data!M2:M1001,">=0",Cleaned_Data!M2:M1001,"<=49.999") -> 291 | C36: =COUNTIFS(Cleaned_Data!M2:M1001,">=0",Cleaned_Data!M2:M1001,"<=49.999",Cleaned_Data!P2:P1001,"Yes") -> 90 | D36: =COUNTIFS(Cleaned_Data!M2:M1001,">=0",Cleaned_Data!M2:M1001,"<=49.999",Cleaned_Data!P2:P1001,"No") -> 201 | E36: =C36/B36 -> 0.30927835
A37: $50–$75 | B37: =COUNTIFS(Cleaned_Data!M2:M1001,">=50",Cleaned_Data!M2:M1001,"<=75") -> 275 | C37: =COUNTIFS(Cleaned_Data!M2:M1001,">=50",Cleaned_Data!M2:M1001,"<=75",Cleaned_Data!P2:P1001,"Yes") -> 71 | D37: =COUNTIFS(Cleaned_Data!M2:M1001,">=50",Cleaned_Data!M2:M1001,"<=75",Cleaned_Data!P2:P1001,"No") -> 204 | E37: =C37/B37 -> 0.25818182
A38: $76–$100 | B38: =COUNTIFS(Cleaned_Data!M2:M1001,">=76",Cleaned_Data!M2:M1001,"<=100") -> 253 | C38: =COUNTIFS(Cleaned_Data!M2:M1001,">=76",Cleaned_Data!M2:M1001,"<=100",Cleaned_Data!P2:P1001,"Yes") -> 84 | D38: =COUNTIFS(Cleaned_Data!M2:M1001,">=76",Cleaned_Data!M2:M1001,"<=100",Cleaned_Data!P2:P1001,"No") -> 169 | E38: =C38/B38 -> 0.33201581
A39: > $100 | B39: =COUNTIFS(Cleaned_Data!M2:M1001,">=100.001",Cleaned_Data!M2:M1001,"<=1000000") -> 172 | C39: =COUNTIFS(Cleaned_Data!M2:M1001,">=100.001",Cleaned_Data!M2:M1001,"<=1000000",Cleaned_Data!P2:P1001,"Yes") -> 62 | D39: =COUNTIFS(Cleaned_Data!M2:M1001,">=100.001",Cleaned_Data!M2:M1001,"<=1000000",Cleaned_Data!P2:P1001,"No") -> 110 | E39: =C39/B39 -> 0.36046512
A41: Churn by Demographics
A42: Senior_Citizen | B42: Total Customers | C42: Churned | D42: Stayed | E42: Churn Rate
A43: Yes | B43: =COUNTIF(Cleaned_Data!C2:C1001,"Yes") -> 285 | C43: =COUNTIFS(Cleaned_Data!C2:C1001,"Yes",Cleaned_Data!P2:P1001,"Yes") -> 88 | D43: =B43-C43 -> 197 | E43: =C43/B43 -> 0.30877193
A44: No | B44: =COUNTIF(Cleaned_Data!C2:C1002,"No") -> 715 | C44: =COUNTIFS(Cleaned_Data!C2:C1002,"No",Cleaned_Data!P2:P1002,"Yes") -> 220 | D44: =B44-C44 -> 495 | E44: =C44/B44 -> 0.30769231
A46: Churn by City
A47: City | B47: Total Customers | C47: Churned | D47: Stayed | E47: Churn Rate
...

Sheet High_Risk_Performance
B3: Column Labels
B4: DSL | D4: Fiber optic | F4: No internet | H4: Total Count of customer_id | I4: Total Sum of Churn_Flag
A5: Row Labels | B5: Count of customer_id | C5: Sum of Churn_Flag | D5: Count of customer_id | E5: Sum of Churn_Flag | F5: Count of customer_id | G5: Sum of Churn_Flag
A6: Month-to-month | B6: 201 | C6: 63 | D6: 236 | E6: 110 | F6: 113 | G6: 38 | H6: 550 | I6: 211
A7: One year | B7: 100 | C7: 20 | D7: 92 | E7: 22 | F7: 56 | G7: 14 | H7: 248 | I7: 56
A8: Two year | B8: 59 | C8: 9 | D8: 102 | E8: 23 | F8: 41 | G8: 9 | H8: 202 | I8: 41
A9: Grand Total | B9: 360 | C9: 92 | D9: 430 | E9: 155 | F9: 210 | G9: 61 | H9: 1000 | I9: 308
C13: Column Labels
C14: Bank Transfer | E14: Credit card | G14: Electronic check | I14: Mailed check | K14: Total Count of customer_id | L14: Total Sum of Churn_Flag
B15: Row Labels | C15: Count of customer_id | D15: Sum of Churn_Flag | E15: Count of customer_id | F15: Sum of Churn_Flag | G15: Count of customer_id | H15: Sum of Churn_Flag | I15: Count of customer_id | J15: Sum of Churn_Flag
B16: Month-to-month | C16: 133 | D16: 52 | E16: 132 | F16: 48 | G16: 199 | H16: 87 | I16: 86 | J16: 24 | K16: 550 | L16: 211
B17: One year | C17: 63 | D17: 15 | E17: 68 | F17: 12 | G17: 74 | H17: 19 | I17: 43 | J17: 10 | K17: 248 | L17: 56
B18: Two year | C18: 53 | D18: 5 | E18: 48 | F18: 11 | G18: 77 | H18: 20 | I18: 24 | J18: 5 | K18: 202 | L18: 41
B19: Grand Total | C19: 249 | D19: 72 | E19: 248 | F19: 71 | G19: 350 | H19: 126 | I19: 153 | J19: 39 | K19: 1000 | L19: 308
B25: Column Labels
B26: 0-12 months | D26: 25-48 months | F26: 49+ months | H26: Total Count of customer_id | I26: Total Sum of Churn_Flag
A27: Row Labels | B27: Count of customer_id | C27: Sum of Churn_Flag | D27: Count of customer_id | E27: Sum of Churn_Flag | F27: Count of customer_id | G27: Sum of Churn_Flag
A28: Month-to-month | B28: 543 | C28: 208 | F28: 7 | G28: 3 | H28: 550 | I28: 211
A29: One year | B29: 244 | C29: 56 | D29: 2 | E29: 0 | F29: 2 | G29: 0 | H29: 248 | I29: 56
A30: Two year | B30: 199 | C30: 40 | D30: 3 | E30: 1 | H30: 202 | I30: 41
A31: Grand Total | B31: 986 | C31: 304 | D31: 5 | E31: 1 | F31: 9 | G31: 3 | H31: 1000 | I31: 308
B42: Column Labels
B43: Month-to-month | D43: One year | F43: Two year | H43: Total Count of customer_id | I43: Total Sum of Churn_Flag
A44: Row Labels | B44: Count of customer_id | C44: Sum of Churn_Flag | D44: Count of customer_id | E44: Sum of Churn_Flag | F44: Count of customer_id | G44: Sum of Churn_Flag
A45: $50-$75 | B45: 158 | C45: 48 | D45: 71 | E45: 20 | F45: 46 | G45: 3 | H45: 275 | I45: 71
A46: $76-$100 | B46: 150 | C46: 59 | D46: 62 | E46: 10 | F46: 50 | G46: 16 | H46: 262 | I46: 85
A47: < $50 | B47: 157 | C47: 59 | D47: 79 | E47: 18 | F47: 55 | G47: 13 | H47: 291 | I47: 90
A48: > $100 | B48: 85 | C48: 45 | D48: 36 | E48: 8 | F48: 51 | G48: 9 | H48: 172 | I48: 62
A49: Grand Total | B49: 550 | C49: 211 | D49: 248 | E49: 56 | F49: 202 | G49: 41 | H49: 1000 | I49: 308

Sheet EDA Dashboard
A1: Customer Churn Analysis Dashboard
A3: Total Customers | F3: Churned_Customers | K3: Stayed_Customers | O3: Churn_Rate
A4: =EDA!B3 -> 1000 | F4: =EDA!B4 -> 308 | K4: =EDA!B5 -> 692 | O4: =EDA!B6 -> 0.308
